src/output/live/WBv3_RET_LIM_EMA9_TRAIL-XAU_USD/XAU_USD/trades.jsonl
{"event": "INIT", "note": "quant-clean retest limits bot started", "schema_version": 3, "dt_utc": "2026-01-28T16:04:21Z"}
{"event": "BOOKS_SAVED", "book_time": "2026-01-28T16:00:00Z", "ref_price": 5278.28, "buy_wall": null, "sell_wall": 5300.0, "schema_version": 3, "dt_utc": "2026-01-28T16:04:21Z"}
{"event": "LIMIT_SKIP_NO_CTX", "book_time": "2026-01-28T16:00:00Z", "schema_version": 3, "dt_utc": "2026-01-28T16:04:21Z"}
{"event": "BOOKS_SAVED", "book_time": "2026-01-28T16:20:00Z", "ref_price": 5287.595, "buy_wall": null, "sell_wall": 5300.0, "schema_version": 3, "dt_utc": "2026-01-28T16:20:06Z"}
{"event": "LIMIT_SKIP_NO_CTX", "book_time": "2026-01-28T16:20:00Z", "schema_version": 3, "dt_utc": "2026-01-28T16:20:06Z"}
{"event": "CANDLES_SAVED", "n_new": 20, "newest": "2026-01-28T16:19:00.000000000Z", "schema_version": 3, "dt_utc": "2026-01-28T16:20:08Z"}
{"event": "BOOKS_SAVED", "book_time": "2026-01-28T16:40:00Z", "ref_price": 5283.19, "buy_wall": null, "sell_wall": 5300.0, "schema_version": 3, "dt_utc": "2026-01-28T16:40:05Z"}
{"event": "LIMIT_SKIP_NO_CTX", "book_time": "2026-01-28T16:40:00Z", "schema_version": 3, "dt_utc": "2026-01-28T16:40:05Z"}
{"event": "CANDLES_SAVED", "n_new": 20, "newest": "2026-01-28T16:39:00.000000000Z", "schema_version": 3, "dt_utc": "2026-01-28T16:40:09Z"}
{"event": "BOOKS_SAVED", "book_time": "2026-01-28T17:00:00Z", "ref_price": 5299.875, "buy_wall": null, "sell_wall": 5303.0, "schema_version": 3, "dt_utc": "2026-01-28T17:00:06Z"}
{"event": "LIMIT_SKIP_CTX_WALL_MISMATCH", "book_time": "2026-01-28T17:00:00Z", "ctx_wall_time": "2026-01-28T16:20:00Z", "books_wall_time": "2026-01-28T17:00:00Z", "schema_version": 3, "dt_utc": "2026-01-28T17:00:06Z"}
{"event": "CANDLES_SAVED", "n_new": 20, "newest": "2026-01-28T16:59:00.000000000Z", "schema_version": 3, "dt_utc": "2026-01-28T17:00:08Z"}
{"event": "BOOKS_SAVED", "book_time": "2026-01-28T17:20:00Z", "ref_price": 5293.365, "buy_wall": 5310.0, "sell_wall": 5314.5, "schema_version": 3, "dt_utc": "2026-01-28T17:20:06Z"}
{"event": "LIMIT_SKIP_CTX_WALL_MISMATCH", "book_time": "2026-01-28T17:20:00Z", "ctx_wall_time": "2026-01-28T16:40:00Z", "books_wall_time": "2026-01-28T17:20:00Z", "schema_version": 3, "dt_utc": "2026-01-28T17:20:06Z"}
{"event": "CANDLES_SAVED", "n_new": 20, "newest": "2026-01-28T17:19:00.000000000Z", "schema_version": 3, "dt_utc": "2026-01-28T17:20:08Z"}
{"event": "BOOKS_SAVED", "book_time": "2026-01-28T17:40:00Z", "ref_price": 5284.895, "buy_wall": null, "sell_wall": null, "schema_version": 3, "dt_utc": "2026-01-28T17:40:06Z"}
{"event": "LIMIT_SKIP_CTX_WALL_MISMATCH", "book_time": "2026-01-28T17:40:00Z", "ctx_wall_time": "2026-01-28T17:00:00Z", "books_wall_time": "2026-01-28T17:40:00Z", "schema_version": 3, "dt_utc": "2026-01-28T17:40:06Z"}
{"event": "CANDLES_SAVED", "n_new": 20, "newest": "2026-01-28T17:39:00.000000000Z", "schema_version": 3, "dt_utc": "2026-01-28T17:40:08Z"}
{"event": "BOOKS_SAVED", "book_time": "2026-01-28T18:00:00Z", "ref_price": 5298.11, "buy_wall": 5310.0, "sell_wall": 5311.0, "schema_version": 3, "dt_utc": "2026-01-28T18:00:06Z"}
{"event": "LIMIT_SKIP_CTX_WALL_MISMATCH", "book_time": "2026-01-28T18:00:00Z", "ctx_wall_time": "2026-01-28T17:20:00Z", "books_wall_time": "2026-01-28T18:00:00Z", "schema_version": 3, "dt_utc": "2026-01-28T18:00:06Z"}
{"event": "CANDLES_SAVED", "n_new": 20, "newest": "2026-01-28T17:59:00.000000000Z", "schema_version": 3, "dt_utc": "2026-01-28T18:00:08Z"}
{"event": "BOOKS_SAVED", "book_time": "2026-01-28T18:20:00Z", "ref_price": 5310.41, "buy_wall": null, "sell_wall": null, "schema_version": 3, "dt_utc": "2026-01-28T18:20:06Z"}
{"event": "LIMIT_SKIP_CTX_WALL_MISMATCH", "book_time": "2026-01-28T18:20:00Z", "ctx_wall_time": "2026-01-28T17:40:00Z", "books_wall_time": "2026-01-28T18:20:00Z", "schema_version": 3, "dt_utc": "2026-01-28T18:20:06Z"}
{"event": "CANDLES_SAVED", "n_new": 20, "newest": "2026-01-28T18:19:00.000000000Z", "schema_version": 3, "dt_utc": "2026-01-28T18:20:08Z"}
{"event": "BOOKS_SAVED", "book_time": "2026-01-28T18:40:00Z", "ref_price": 5274.17, "buy_wall": null, "sell_wall": null, "schema_version": 3, "dt_utc": "2026-01-28T18:40:06Z"}
{"event": "LIMIT_SKIP_CTX_WALL_MISMATCH", "book_time": "2026-01-28T18:40:00Z", "ctx_wall_time": "2026-01-28T18:00:00Z", "books_wall_time": "2026-01-28T18:40:00Z", "schema_version": 3, "dt_utc": "2026-01-28T18:40:06Z"}
{"event": "CANDLES_SAVED", "n_new": 20, "newest": "2026-01-28T18:39:00.000000000Z", "schema_version": 3, "dt_utc": "2026-01-28T18:40:08Z"}
{"event": "BOOKS_SAVED", "book_time": "2026-01-28T19:00:00Z", "ref_price": 5282.595, "buy_wall": null, "sell_wall": 5270.0, "schema_version": 3, "dt_utc": "2026-01-28T19:00:06Z"}
{"event": "LIMIT_SKIP_CTX_WALL_MISMATCH", "book_time": "2026-01-28T19:00:00Z", "ctx_wall_time": "2026-01-28T18:20:00Z", "books_wall_time": "2026-01-28T19:00:00Z", "schema_version": 3, "dt_utc": "2026-01-28T19:00:06Z"}
{"event": "CANDLES_SAVED", "n_new": 20, "newest": "2026-01-28T18:59:00.000000000Z", "schema_version": 3, "dt_utc": "2026-01-28T19:00:08Z"}
{"event": "BOOKS_SAVED", "book_time": "2026-01-28T19:20:00Z", "ref_price": 5296.75, "buy_wall": 5310.0, "sell_wall": null, "schema_version": 3, "dt_utc": "2026-01-28T19:20:05Z"}
{"event": "LIMIT_SKIP_CTX_WALL_MISMATCH", "book_time": "2026-01-28T19:20:00Z", "ctx_wall_time": "2026-01-28T18:40:00Z", "books_wall_time": "2026-01-28T19:20:00Z", "schema_version": 3, "dt_utc": "2026-01-28T19:20:05Z"}
{"event": "CANDLES_SAVED", "n_new": 20, "newest": "2026-01-28T19:19:00.000000000Z", "schema_version": 3, "dt_utc": "2026-01-28T19:20:09Z"}
{"event": "BOOKS_SAVED", "book_time": "2026-01-28T19:40:00Z", "ref_price": 5301.035, "buy_wall": 5310.0, "sell_wall": null, "schema_version": 3, "dt_utc": "2026-01-28T19:40:05Z"}
{"event": "LIMIT_SKIP_CTX_WALL_MISMATCH", "book_time": "2026-01-28T19:40:00Z", "ctx_wall_time": "2026-01-28T19:00:00Z", "books_wall_time": "2026-01-28T19:40:00Z", "schema_version": 3, "dt_utc": "2026-01-28T19:40:05Z"}
{"event": "CANDLES_SAVED", "n_new": 20, "newest": "2026-01-28T19:39:00.000000000Z", "schema_version": 3, "dt_utc": "2026-01-28T19:40:08Z"}
{"event": "BOOKS_SAVED", "book_time": "2026-01-28T20:00:00Z", "ref_price": 5325.42, "buy_wall": null, "sell_wall": 5350.0, "schema_version": 3, "dt_utc": "2026-01-28T20:00:06Z"}
{"event": "LIMIT_SKIP_CTX_WALL_MISMATCH", "book_time": "2026-01-28T20:00:00Z", "ctx_wall_time": "2026-01-28T19:20:00Z", "books_wall_time": "2026-01-28T20:00:00Z", "schema_version": 3, "dt_utc": "2026-01-28T20:00:06Z"}
{"event": "CANDLES_SAVED", "n_new": 20, "newest": "2026-01-28T19:59:00.000000000Z", "schema_version": 3, "dt_utc": "2026-01-28T20:00:08Z"}
{"event": "BOOKS_SAVED", "book_time": "2026-01-28T20:20:00Z", "ref_price": 5338.735, "buy_wall": null, "sell_wall": 5350.0, "schema_version": 3, "dt_utc": "2026-01-28T20:20:05Z"}
{"event": "LIMIT_SKIP_CTX_WALL_MISMATCH", "book_time": "2026-01-28T20:20:00Z", "ctx_wall_time": "2026-01-28T19:40:00Z", "books_wall_time": "2026-01-28T20:20:00Z", "schema_version": 3, "dt_utc": "2026-01-28T20:20:05Z"}
{"event": "CANDLES_SAVED", "n_new": 20, "newest": "2026-01-28T20:19:00.000000000Z", "schema_version": 3, "dt_utc": "2026-01-28T20:20:08Z"}
{"event": "BOOKS_SAVED", "book_time": "2026-01-28T20:40:00Z", "ref_price": 5376.43, "buy_wall": 5381.5, "sell_wall": 5380.0, "schema_version": 3, "dt_utc": "2026-01-28T20:40:05Z"}
{"event": "LIMIT_SKIP_CTX_WALL_MISMATCH", "book_time": "2026-01-28T20:40:00Z", "ctx_wall_time": "2026-01-28T20:00:00Z", "books_wall_time": "2026-01-28T20:40:00Z", "schema_version": 3, "dt_utc": "2026-01-28T20:40:05Z"}
{"event": "CANDLES_SAVED", "n_new": 20, "newest": "2026-01-28T20:39:00.000000000Z", "schema_version": 3, "dt_utc": "2026-01-28T20:40:08Z"}
{"event": "BOOKS_SAVED", "book_time": "2026-01-28T21:00:00Z", "ref_price": 5376.965, "buy_wall": 5400.0, "sell_wall": null, "schema_version": 3, "dt_utc": "2026-01-28T21:00:06Z"}
{"event": "LIMIT_SKIP_CTX_WALL_MISMATCH", "book_time": "2026-01-28T21:00:00Z", "ctx_wall_time": "2026-01-28T20:20:00Z", "books_wall_time": "2026-01-28T21:00:00Z", "schema_version": 3, "dt_utc": "2026-01-28T21:00:06Z"}
